Traceback (most recent call last):
  File "/usr/lib/python3/dist-packages/urllib3/connection.py", line 203, in _new_conn
    sock = connection.create_connection(
           ^^^^^^^^^^^^^^^^^^^^^^^^^^^^^
  File "/usr/lib/python3/dist-packages/urllib3/util/connection.py", line 60, in create_connection
    for res in socket.getaddrinfo(host, port, family, socket.SOCK_STREAM):
               ^^^^^^^^^^^^^^^^^^^^^^^^^^^^^^^^^^^^^^^^^^^^^^^^^^^^^^^^^^
  File "/usr/lib/python3.12/socket.py", line 963, in getaddrinfo
    for res in _socket.getaddrinfo(host, port, family, type, proto, flags):
               ^^^^^^^^^^^^^^^^^^^^^^^^^^^^^^^^^^^^^^^^^^^^^^^^^^^^^^^^^^^
socket.gaierror: [Errno -3] Temporary failure in name resolution

The above exception was the direct cause of the following exception:

Traceback (most recent call last):
  File "/usr/lib/python3/dist-packages/urllib3/connectionpool.py", line 791, in urlopen
    response = self._make_request(
               ^^^^^^^^^^^^^^^^^^^
  File "/usr/lib/python3/dist-packages/urllib3/connectionpool.py", line 492, in _make_request
    raise new_e
  File "/usr/lib/python3/dist-packages/urllib3/connectionpool.py", line 468, in _make_request
    self._validate_conn(conn)
  File "/usr/lib/python3/dist-packages/urllib3/connectionpool.py", line 1097, in _validate_conn
    conn.connect()
  File "/usr/lib/python3/dist-packages/urllib3/connection.py", line 611, in connect
    self.sock = sock = self._new_conn()
                       ^^^^^^^^^^^^^^^^
  File "/usr/lib/python3/dist-packages/urllib3/connection.py", line 210, in _new_conn
    raise NameResolutionError(self.host, self, e) from e
urllib3.exceptions.NameResolutionError: <urllib3.connection.HTTPSConnection object at 0x73b7403456d0>: Failed to resolve 'fuel.gazebosim.org' ([Errno -3] Temporary failure in name resolution)

The above exception was the direct cause of the following exception:

Traceback (most recent call last):
  File "/usr/lib/python3/dist-packages/requests/adapters.py", line 486, in send
    resp = conn.urlopen(
           ^^^^^^^^^^^^^
  File "/usr/lib/python3/dist-packages/urllib3/connectionpool.py", line 845, in urlopen
    retries = retries.increment(
              ^^^^^^^^^^^^^^^^^^
  File "/usr/lib/python3/dist-packages/urllib3/util/retry.py", line 517, in increment
    raise MaxRetryError(_pool, url, reason) from reason  # type: ignore[arg-type]
    ^^^^^^^^^^^^^^^^^^^^^^^^^^^^^^^^^^^^^^^^^^^^^^^^^^^
urllib3.exceptions.MaxRetryError: HTTPSConnectionPool(host='fuel.gazebosim.org', port=443): Max retries exceeded with url: /1.0/models?page=1&per_page=100 (Caused by NameResolutionError("<urllib3.connection.HTTPSConnection object at 0x73b7403456d0>: Failed to resolve 'fuel.gazebosim.org' ([Errno -3] Temporary failure in name resolution)"))

During handling of the above exception, another exception occurred:

Traceback (most recent call last):
  File "/rmf_demos_ws/install/rmf_building_map_tools/lib/rmf_building_map_tools/building_map_model_downloader", line 33, in <module>
    sys.exit(load_entry_point('rmf-building-map-tools==1.11.0', 'console_scripts', 'building_map_model_downloader')())
             ^^^^^^^^^^^^^^^^^^^^^^^^^^^^^^^^^^^^^^^^^^^^^^^^^^^^^^^^^^^^^^^^^^^^^^^^^^^^^^^^^^^^^^^^^^^^^^^^^^^^^^^^
  File "/rmf_demos_ws/install/rmf_building_map_tools/lib/python3.12/site-packages/building_map_model_downloader/building_map_model_downloader.py", line 217, in main
    download_models(
  File "/rmf_demos_ws/install/rmf_building_map_tools/lib/python3.12/site-packages/building_map_model_downloader/building_map_model_downloader.py", line 134, in download_models
    missing_models = pit_crew.get_missing_models(
                     ^^^^^^^^^^^^^^^^^^^^^^^^^^^^
  File "/rmf_demos_ws/install/rmf_building_map_tools/lib/python3.12/site-packages/pit_crew/pit_crew.py", line 153, in get_missing_models
    cache = build_and_update_cache(cache_file_path=cache_file_path,
            ^^^^^^^^^^^^^^^^^^^^^^^^^^^^^^^^^^^^^^^^^^^^^^^^^^^^^^^
  File "/rmf_demos_ws/install/rmf_building_map_tools/lib/python3.12/site-packages/pit_crew/pit_crew.py", line 847, in build_and_update_cache
    resp = requests.get("%s?page=%d&per_page=100" % (url_base, page))
           ^^^^^^^^^^^^^^^^^^^^^^^^^^^^^^^^^^^^^^^^^^^^^^^^^^^^^^^^^^
  File "/usr/lib/python3/dist-packages/requests/api.py", line 73, in get
    return request("get", url, params=params, **kwargs)
           ^^^^^^^^^^^^^^^^^^^^^^^^^^^^^^^^^^^^^^^^^^^^
  File "/usr/lib/python3/dist-packages/requests/api.py", line 59, in request
    return session.request(method=method, url=url, **kwargs)
           ^^^^^^^^^^^^^^^^^^^^^^^^^^^^^^^^^^^^^^^^^^^^^^^^^
  File "/usr/lib/python3/dist-packages/requests/sessions.py", line 589, in request
    resp = self.send(prep, **send_kwargs)
           ^^^^^^^^^^^^^^^^^^^^^^^^^^^^^^
  File "/usr/lib/python3/dist-packages/requests/sessions.py", line 703, in send
    r = adapter.send(request, **kwargs)
        ^^^^^^^^^^^^^^^^^^^^^^^^^^^^^^^
  File "/usr/lib/python3/dist-packages/requests/adapters.py", line 519, in send
    raise ConnectionError(e, request=request)
requests.exceptions.ConnectionError: HTTPSConnectionPool(host='fuel.gazebosim.org', port=443): Max retries exceeded with url: /1.0/models?page=1&per_page=100 (Caused by NameResolutionError("<urllib3.connection.HTTPSConnection object at 0x73b7403456d0>: Failed to resolve 'fuel.gazebosim.org' ([Errno -3] Temporary failure in name resolution)"))
gmake[2]: *** [CMakeFiles/generate_library_crowdsim.dir/build.make:78: maps/library/library.world] Error 1
gmake[2]: *** Deleting file 'maps/library/library.world'
gmake[1]: *** [CMakeFiles/Makefile2:139: CMakeFiles/generate_library_crowdsim.dir/all] Error 2
gmake: *** [Makefile:146: all] Error 2
